Workbook

Sheet Actual Expenses
B2: Start Date | C2: 45559
B4: Actual Operating Expenses
B5: Account # | C5: Department | D5: Description
B6: 11256 | C6: Marketing | D6: Paid Ads | E6: 22992 | F6: 24001 | G6: 26558 | H6: 25446
B7: 11257 | C7: Marketing | D7: Infuencers | E7: 53326 | F7: 54223 | G7: 51000 | H7: 50000
B8: 11259 | C8: Engineering | D8: Consulting | E8: 35888 | F8: 36880 | G8: 37995 | H8: 40000
B9: 11260 | C9: Engineering | D9: Travel | E9: 87942 | F9: 85224 | G9: 82469 | H9: 81005
B10: 11263 | C10: Support | D10: Software | E10: 92622 | F10: 90005 | G10: 87556 | H10: 84522
B11: 11264 | C11: Support | D11: Call Center | E11: 27416 | F11: 26554 | G11: 24330 | H11: 22338
B12: 11267 | C12: HR | D12: Recruiting Events | E12: 41696 | F12: 41696 | G12: 42558 | H12: 45448
B13: 11268 | C13: HR | D13: Meetups | E13: 60285 | F13: 61225 | G13: 68994 | H13: 72410

Sheet Forecast
B1: Best | C1: 0.3
B2: Worst | C2: 0.3
B4: 1. Live Case | E4: Actuals | I4: Forecast
B5: Account # | C5: Department | D5: Description | E5: 45559 | F5: 45589 | G5: 45620 | H5: 45650 | I5: 45681 | J5: 45712 | K5: 45740 | L5: 45771 | M5: 45801 | N5: 45832 | O5: 45862 | P5: 45893 | Q5: 45924 | R5: 45954 | S5: 45985 | T5: 46015
B6: 11256 | C6: Marketing | D6: Paid Ads | E6: 22992 | F6: 24001 | G6: 26558 | H6: 25446 | I6: =CHOOSE('Income Statement'!$C$2,Forecast!I17,Forecast!I28,Forecast!I39) -> 18801.833 | J6: =CHOOSE('Income Statement'!$C$2,Forecast!J17,Forecast!J28,Forecast!J39) -> 18845.815 | K6: =CHOOSE('Income Statement'!$C$2,Forecast!K17,Forecast!K28,Forecast!K39) -> 19992.154 | L6: =CHOOSE('Income Statement'!$C$2,Forecast!L17,Forecast!L28,Forecast!L39) -> 19951.002 | M6: =CHOOSE('Income Statement'!$C$2,Forecast!M17,Forecast!M28,Forecast!M39) -> 21070.943 | N6: =CHOOSE('Income Statement'!$C$2,Forecast!N17,Forecast!N28,Forecast!N39) -> 21078.203 | O6: =CHOOSE('Income Statement'!$C$2,Forecast!O17,Forecast!O28,Forecast!O39) -> 22170.533 | P6: =CHOOSE('Income Statement'!$C$2,Forecast!P17,Forecast!P28,Forecast!P39) -> 22178.407 | ... T6: =CHOOSE('Income Statement'!$C$2,Forecast!T17,Forecast!T28,Forecast!T39) -> 24371.809
B7: 11257 | C7: Marketing | D7: Infuencers | E7: 53326 | F7: 54223 | G7: 51000 | H7: 50000 | I7: =CHOOSE('Income Statement'!$C$2,Forecast!I18,Forecast!I29,Forecast!I40) -> 34200.981 | J7: =CHOOSE('Income Statement'!$C$2,Forecast!J18,Forecast!J29,Forecast!J40) -> 33310.176 | K7: =CHOOSE('Income Statement'!$C$2,Forecast!K18,Forecast!K29,Forecast!K40) -> 32090.815 | L7: =CHOOSE('Income Statement'!$C$2,Forecast!L18,Forecast!L29,Forecast!L40) -> 31213.974 | M7: =CHOOSE('Income Statement'!$C$2,Forecast!M18,Forecast!M29,Forecast!M40) -> 30010.158 | N7: =CHOOSE('Income Statement'!$C$2,Forecast!N18,Forecast!N29,Forecast!N40) -> 29161.646 | O7: =CHOOSE('Income Statement'!$C$2,Forecast!O18,Forecast!O29,Forecast!O40) -> 27790.839 | P7: =CHOOSE('Income Statement'!$C$2,Forecast!P18,Forecast!P29,Forecast!P40) -> 26969.094 | ... T7: =CHOOSE('Income Statement'!$C$2,Forecast!T18,Forecast!T29,Forecast!T40) -> 22623.486
B8: 11259 | C8: Engineering | D8: Consulting | E8: 35888 | F8: 36880 | G8: 37995 | H8: 40000 | I8: =CHOOSE('Income Statement'!$C$2,Forecast!I19,Forecast!I30,Forecast!I41) -> 28828.78 | J8: =CHOOSE('Income Statement'!$C$2,Forecast!J19,Forecast!J30,Forecast!J41) -> 29829.57 | K8: =CHOOSE('Income Statement'!$C$2,Forecast!K19,Forecast!K30,Forecast!K41) -> 30825.318 | L8: =CHOOSE('Income Statement'!$C$2,Forecast!L19,Forecast!L30,Forecast!L41) -> 31789.738 | M8: =CHOOSE('Income Statement'!$C$2,Forecast!M19,Forecast!M30,Forecast!M41) -> 32770.197 | N8: =CHOOSE('Income Statement'!$C$2,Forecast!N19,Forecast!N30,Forecast!N41) -> 33750.718 | O8: =CHOOSE('Income Statement'!$C$2,Forecast!O19,Forecast!O30,Forecast!O41) -> 34731.303 | P8: =CHOOSE('Income Statement'!$C$2,Forecast!P19,Forecast!P30,Forecast!P41) -> 35711.936 | ... T8: =CHOOSE('Income Statement'!$C$2,Forecast!T19,Forecast!T30,Forecast!T41) -> 39634.614
B9: 11260 | C9: Engineering | D9: Travel | E9: 87942 | F9: 85224 | G9: 82469 | H9: 81005 | I9: =CHOOSE('Income Statement'!$C$2,Forecast!I20,Forecast!I31,Forecast!I42) -> 54899.524 | J9: =CHOOSE('Income Statement'!$C$2,Forecast!J20,Forecast!J31,Forecast!J42) -> 53324.63 | K9: =CHOOSE('Income Statement'!$C$2,Forecast!K20,Forecast!K31,Forecast!K42) -> 51738.726 | L9: =CHOOSE('Income Statement'!$C$2,Forecast!L20,Forecast!L31,Forecast!L42) -> 50128.337 | M9: =CHOOSE('Income Statement'!$C$2,Forecast!M20,Forecast!M31,Forecast!M42) -> 48532.325 | N9: =CHOOSE('Income Statement'!$C$2,Forecast!N20,Forecast!N31,Forecast!N42) -> 46935.402 | O9: =CHOOSE('Income Statement'!$C$2,Forecast!O20,Forecast!O31,Forecast!O42) -> 45337.88 | P9: =CHOOSE('Income Statement'!$C$2,Forecast!P20,Forecast!P31,Forecast!P42) -> 43736.51 | ... T9: =CHOOSE('Income Statement'!$C$2,Forecast!T20,Forecast!T31,Forecast!T42) -> 37341.371
B10: 11263 | C10: Support | D10: Software | E10: 92622 | F10: 90005 | G10: 87556 | H10: 84522 | I10: =CHOOSE('Income Statement'!$C$2,Forecast!I21,Forecast!I32,Forecast!I43) -> 57341.814 | J10: =CHOOSE('Income Statement'!$C$2,Forecast!J21,Forecast!J32,Forecast!J43) -> 55444.485 | K10: =CHOOSE('Income Statement'!$C$2,Forecast!K21,Forecast!K32,Forecast!K43) -> 53538.415 | L10: =CHOOSE('Income Statement'!$C$2,Forecast!L21,Forecast!L32,Forecast!L43) -> 51654.742 | M10: =CHOOSE('Income Statement'!$C$2,Forecast!M21,Forecast!M32,Forecast!M43) -> 49760.338 | N10: =CHOOSE('Income Statement'!$C$2,Forecast!N21,Forecast!N32,Forecast!N43) -> 47787.432 | O10: =CHOOSE('Income Statement'!$C$2,Forecast!O21,Forecast!O32,Forecast!O43) -> 45936.576 | P10: =CHOOSE('Income Statement'!$C$2,Forecast!P21,Forecast!P32,Forecast!P43) -> 44068.577 | ... T10: =CHOOSE('Income Statement'!$C$2,Forecast!T21,Forecast!T32,Forecast!T43) -> 36391.145
B11: 11264 | C11: Support | D11: Call Center | E11: 27416 | F11: 26554 | G11: 24330 | H11: 22338 | I11: =CHOOSE('Income Statement'!$C$2,Forecast!I22,Forecast!I33,Forecast!I44) -> 14549.274 | J11: =CHOOSE('Income Statement'!$C$2,Forecast!J22,Forecast!J33,Forecast!J44) -> 13276.457 | K11: =CHOOSE('Income Statement'!$C$2,Forecast!K22,Forecast!K33,Forecast!K44) -> 11997.136 | L11: =CHOOSE('Income Statement'!$C$2,Forecast!L22,Forecast!L33,Forecast!L44) -> 10778.931 | M11: =CHOOSE('Income Statement'!$C$2,Forecast!M22,Forecast!M33,Forecast!M44) -> 9537.5757 | N11: =CHOOSE('Income Statement'!$C$2,Forecast!N22,Forecast!N33,Forecast!N44) -> 8021.7835 | O11: =CHOOSE('Income Statement'!$C$2,Forecast!O22,Forecast!O33,Forecast!O44) -> 7164.9997 | P11: =CHOOSE('Income Statement'!$C$2,Forecast!P22,Forecast!P33,Forecast!P44) -> 5789.8934 | ... T11: =CHOOSE('Income Statement'!$C$2,Forecast!T22,Forecast!T33,Forecast!T44) -> 578.13463
B12: 11267 | C12: HR | D12: Recruiting Events | E12: 41696 | F12: 41696 | G12: 42558 | H12: 45448 | I12: =CHOOSE('Income Statement'!$C$2,Forecast!I23,Forecast!I34,Forecast!I45) -> 32379.863 | J12: =CHOOSE('Income Statement'!$C$2,Forecast!J23,Forecast!J34,Forecast!J45) -> 33393.247 | K12: =CHOOSE('Income Statement'!$C$2,Forecast!K23,Forecast!K34,Forecast!K45) -> 34405.12 | L12: =CHOOSE('Income Statement'!$C$2,Forecast!L23,Forecast!L34,Forecast!L45) -> 35316.63 | M12: =CHOOSE('Income Statement'!$C$2,Forecast!M23,Forecast!M34,Forecast!M45) -> 36277.04 | N12: =CHOOSE('Income Statement'!$C$2,Forecast!N23,Forecast!N34,Forecast!N45) -> 37237.62 | O12: =CHOOSE('Income Statement'!$C$2,Forecast!O23,Forecast!O34,Forecast!O45) -> 38198.382 | P12: =CHOOSE('Income Statement'!$C$2,Forecast!P23,Forecast!P34,Forecast!P45) -> 39159.274 | ... T12: =CHOOSE('Income Statement'!$C$2,Forecast!T23,Forecast!T34,Forecast!T45) -> 43003.214
B13: 11268 | C13: HR | D13: Meetups | E13: 60285 | F13: 61225 | G13: 68994 | H13: 72410 | I13: =CHOOSE('Income Statement'!$C$2,Forecast!I24,Forecast!I35,Forecast!I46) -> 53693.925 | J13: =CHOOSE('Income Statement'!$C$2,Forecast!J24,Forecast!J35,Forecast!J46) -> 56511.928 | K13: =CHOOSE('Income Statement'!$C$2,Forecast!K24,Forecast!K35,Forecast!K46) -> 60962.76 | L13: =CHOOSE('Income Statement'!$C$2,Forecast!L24,Forecast!L35,Forecast!L46) -> 63613.011 | M13: =CHOOSE('Income Statement'!$C$2,Forecast!M24,Forecast!M35,Forecast!M46) -> 67863.644 | N13: =CHOOSE('Income Statement'!$C$2,Forecast!N24,Forecast!N35,Forecast!N46) -> 70560.152 | O13: =CHOOSE('Income Statement'!$C$2,Forecast!O24,Forecast!O35,Forecast!O46) -> 74806.187 | P13: =CHOOSE('Income Statement'!$C$2,Forecast!P24,Forecast!P35,Forecast!P46) -> 77725.223 | ... T13: =CHOOSE('Income Statement'!$C$2,Forecast!T24,Forecast!T35,Forecast!T46) -> 91760.115
B15: 1. Best Case | E15: Actuals | I15: Forecast
A16: x | B16: Account # | C16: Department | D16: Description | E16: 45559 | F16: 45589 | G16: 45620 | H16: 45650 | I16: 45681 | J16: 45712 | K16: 45740 | L16: 45771 | M16: 45801 | N16: 45832 | O16: 45862 | P16: 45893 | Q16: 45924 | R16: 45954 | S16: 45985 | T16: 46015
B17: 11256 | C17: Marketing | D17: Paid Ads | E17: 22992 | F17: 24001 | G17: 26558 | H17: 25446 | I17: =I28*(1-$C$1) -> 18801.833 | J17: =J28*(1-$C$1) -> 18845.815 | K17: =K28*(1-$C$1) -> 19992.154 | L17: =L28*(1-$C$1) -> 19951.002 | M17: =M28*(1-$C$1) -> 21070.943 | N17: =N28*(1-$C$1) -> 21078.203 | O17: =O28*(1-$C$1) -> 22170.533 | P17: =P28*(1-$C$1) -> 22178.407 | ... T17: =T28*(1-$C$1) -> 24371.809
B18: 11257 | C18: Marketing | D18: Infuencers | E18: 53326 | F18: 54223 | G18: 51000 | H18: 50000 | I18: =I29*(1-$C$1) -> 34200.981 | J18: =J29*(1-$C$1) -> 33310.176 | K18: =K29*(1-$C$1) -> 32090.815 | L18: =L29*(1-$C$1) -> 31213.974 | M18: =M29*(1-$C$1) -> 30010.158 | N18: =N29*(1-$C$1) -> 29161.646 | O18: =O29*(1-$C$1) -> 27790.839 | P18: =P29*(1-$C$1) -> 26969.094 | ... T18: =T29*(1-$C$1) -> 22623.486
B19: 11259 | C19: Engineering | D19: Consulting | E19: 35888 | F19: 36880 | G19: 37995 | H19: 40000 | I19: =I30*(1-$C$1) -> 28828.78 | J19: =J30*(1-$C$1) -> 29829.57 | K19: =K30*(1-$C$1) -> 30825.318 | L19: =L30*(1-$C$1) -> 31789.738 | M19: =M30*(1-$C$1) -> 32770.197 | N19: =N30*(1-$C$1) -> 33750.718 | O19: =O30*(1-$C$1) -> 34731.303 | P19: =P30*(1-$C$1) -> 35711.936 | ... T19: =T30*(1-$C$1) -> 39634.614
B20: 11260 | C20: Engineering | D20: Travel | E20: 87942 | F20: 85224 | G20: 82469 | H20: 81005 | I20: =I31*(1-$C$1) -> 54899.524 | J20: =J31*(1-$C$1) -> 53324.63 | K20: =K31*(1-$C$1) -> 51738.726 | L20: =L31*(1-$C$1) -> 50128.337 | M20: =M31*(1-$C$1) -> 48532.325 | N20: =N31*(1-$C$1) -> 46935.402 | O20: =O31*(1-$C$1) -> 45337.88 | P20: =P31*(1-$C$1) -> 43736.51 | ... T20: =T31*(1-$C$1) -> 37341.371
B21: 11263 | C21: Support | D21: Software | E21: 92622 | F21: 90005 | G21: 87556 | H21: 84522 | I21: =I32*(1-$C$1) -> 57341.814 | J21: =J32*(1-$C$1) -> 55444.485 | K21: =K32*(1-$C$1) -> 53538.415 | L21: =L32*(1-$C$1) -> 51654.742 | M21: =M32*(1-$C$1) -> 49760.338 | N21: =N32*(1-$C$1) -> 47787.432 | O21: =O32*(1-$C$1) -> 45936.576 | P21: =P32*(1-$C$1) -> 44068.577 | ... T21: =T32*(1-$C$1) -> 36391.145
B22: 11264 | C22: Support | D22: Call Center | E22: 27416 | F22: 26554 | G22: 24330 | H22: 22338 | I22: =I33*(1-$C$1) -> 14549.274 | J22: =J33*(1-$C$1) -> 13276.457 | K22: =K33*(1-$C$1) -> 11997.136 | L22: =L33*(1-$C$1) -> 10778.931 | M22: =M33*(1-$C$1) -> 9537.5757 | N22: =N33*(1-$C$1) -> 8021.7835 | O22: =O33*(1-$C$1) -> 7164.9997 | P22: =P33*(1-$C$1) -> 5789.8934 | ... T22: =T33*(1-$C$1) -> 578.13463
B23: 11267 | C23: HR | D23: Recruiting Events | E23: 41696 | F23: 41696 | G23: 42558 | H23: 45448 | I23: =I34*(1-$C$1) -> 32379.863 | J23: =J34*(1-$C$1) -> 33393.247 | K23: =K34*(1-$C$1) -> 34405.12 | L23: =L34*(1-$C$1) -> 35316.63 | M23: =M34*(1-$C$1) -> 36277.04 | N23: =N34*(1-$C$1) -> 37237.62 | O23: =O34*(1-$C$1) -> 38198.382 | P23: =P34*(1-$C$1) -> 39159.274 | ... T23: =T34*(1-$C$1) -> 43003.214
B24: 11268 | C24: HR | D24: Meetups | E24: 60285 | F24: 61225 | G24: 68994 | H24: 72410 | I24: =I35*(1-$C$1) -> 53693.925 | J24: =J35*(1-$C$1) -> 56511.928 | K24: =K35*(1-$C$1) -> 60962.76 | L24: =L35*(1-$C$1) -> 63613.011 | M24: =M35*(1-$C$1) -> 67863.644 | N24: =N35*(1-$C$1) -> 70560.152 | O24: =O35*(1-$C$1) -> 74806.187 | P24: =P35*(1-$C$1) -> 77725.223 | ... T24: =T35*(1-$C$1) -> 91760.115
B26: 2. Base Case | E26: Actuals | I26: Forecast
A27: x | B27: Account # | C27: Department | D27: Description | E27: 45559 | F27: 45589 | G27: 45620 | H27: 45650 | I27: 45681 | J27: 45712 | K27: 45740 | L27: 45771 | M27: 45801 | N27: 45832 | O27: 45862 | P27: 45893 | Q27: 45924 | R27: 45954 | S27: 45985 | T27: 46015
B28: 11256 | C28: Marketing | D28: Paid Ads | E28: 22992 | F28: 24001 | G28: 26558 | H28: 25446 | I28: =_xlfn.FORECAST.ETS(I$27,$E28:H28,$E$27:H$27) -> 26859.761 | J28: =_xlfn.FORECAST.ETS(J$27,$E28:I28,$E$27:I$27) -> 26922.594 | K28: =_xlfn.FORECAST.ETS(K$27,$E28:J28,$E$27:J$27) -> 28560.22 | L28: =_xlfn.FORECAST.ETS(L$27,$E28:K28,$E$27:K$27) -> 28501.432 | M28: =_xlfn.FORECAST.ETS(M$27,$E28:L28,$E$27:L$27) -> 30101.347 | N28: =_xlfn.FORECAST.ETS(N$27,$E28:M28,$E$27:M$27) -> 30111.719 | O28: =_xlfn.FORECAST.ETS(O$27,$E28:N28,$E$27:N$27) -> 31672.189 | P28: =_xlfn.FORECAST.ETS(P$27,$E28:O28,$E$27:O$27) -> 31683.439 | ... T28: =_xlfn.FORECAST.ETS(T$27,$E28:S28,$E$27:S$27) -> 34816.87
B29: 11257 | C29: Marketing | D29: Infuencers | E29: 53326 | F29: 54223 | G29: 51000 | H29: 50000 | I29: =_xlfn.FORECAST.ETS(I$27,$E29:H29,$E$27:H$27) -> 48858.544 | J29: =_xlfn.FORECAST.ETS(J$27,$E29:I29,$E$27:I$27) -> 47585.966 | K29: =_xlfn.FORECAST.ETS(K$27,$E29:J29,$E$27:J$27) -> 45844.021 | L29: =_xlfn.FORECAST.ETS(L$27,$E29:K29,$E$27:K$27) -> 44591.391 | M29: =_xlfn.FORECAST.ETS(M$27,$E29:L29,$E$27:L$27) -> 42871.655 | N29: =_xlfn.FORECAST.ETS(N$27,$E29:M29,$E$27:M$27) -> 41659.495 | O29: =_xlfn.FORECAST.ETS(O$27,$E29:N29,$E$27:N$27) -> 39701.198 | P29: =_xlfn.FORECAST.ETS(P$27,$E29:O29,$E$27:O$27) -> 38527.277 | ... T29: =_xlfn.FORECAST.ETS(T$27,$E29:S29,$E$27:S$27) -> 32319.266
B30: 11259 | C30: Engineering | D30: Consulting | E30: 35888 | F30: 36880 | G30: 37995 | H30: 40000 | I30: =_xlfn.FORECAST.ETS(I$27,$E30:H30,$E$27:H$27) -> 41183.971 | J30: =_xlfn.FORECAST.ETS(J$27,$E30:I30,$E$27:I$27) -> 42613.672 | K30: =_xlfn.FORECAST.ETS(K$27,$E30:J30,$E$27:J$27) -> 44036.168 | L30: =_xlfn.FORECAST.ETS(L$27,$E30:K30,$E$27:K$27) -> 45413.912 | M30: =_xlfn.FORECAST.ETS(M$27,$E30:L30,$E$27:L$27) -> 46814.567 | N30: =_xlfn.FORECAST.ETS(N$27,$E30:M30,$E$27:M$27) -> 48215.311 | O30: =_xlfn.FORECAST.ETS(O$27,$E30:N30,$E$27:N$27) -> 49616.148 | P30: =_xlfn.FORECAST.ETS(P$27,$E30:O30,$E$27:O$27) -> 51017.052 | ... T30: =_xlfn.FORECAST.ETS(T$27,$E30:S30,$E$27:S$27) -> 56620.877
B31: 11260 | C31: Engineering | D31: Travel | E31: 87942 | F31: 85224 | G31: 82469 | H31: 81005 | I31: =_xlfn.FORECAST.ETS(I$27,$E31:H31,$E$27:H$27) -> 78427.892 | J31: =_xlfn.FORECAST.ETS(J$27,$E31:I31,$E$27:I$27) -> 76178.043 | K31: =_xlfn.FORECAST.ETS(K$27,$E31:J31,$E$27:J$27) -> 73912.465 | L31: =_xlfn.FORECAST.ETS(L$27,$E31:K31,$E$27:K$27) -> 71611.91 | M31: =_xlfn.FORECAST.ETS(M$27,$E31:L31,$E$27:L$27) -> 69331.893 | N31: =_xlfn.FORECAST.ETS(N$27,$E31:M31,$E$27:M$27) -> 67050.575 | O31: =_xlfn.FORECAST.ETS(O$27,$E31:N31,$E$27:N$27) -> 64768.401 | P31: =_xlfn.FORECAST.ETS(P$27,$E31:O31,$E$27:O$27) -> 62480.729 | ... T31: =_xlfn.FORECAST.ETS(T$27,$E31:S31,$E$27:S$27) -> 53344.816
B32: 11263 | C32: Support | D32: Software | E32: 92622 | F32: 90005 | G32: 87556 | H32: 84522 | I32: =_xlfn.FORECAST.ETS(I$27,$E32:H32,$E$27:H$27) -> 81916.877 | J32: =_xlfn.FORECAST.ETS(J$27,$E32:I32,$E$27:I$27) -> 79206.408 | K32: =_xlfn.FORECAST.ETS(K$27,$E32:J32,$E$27:J$27) -> 76483.45 | L32: =_xlfn.FORECAST.ETS(L$27,$E32:K32,$E$27:K$27) -> 73792.488 | M32: =_xlfn.FORECAST.ETS(M$27,$E32:L32,$E$27:L$27) -> 71086.198 | N32: =_xlfn.FORECAST.ETS(N$27,$E32:M32,$E$27:M$27) -> 68267.761 | O32: =_xlfn.FORECAST.ETS(O$27,$E32:N32,$E$27:N$27) -> 65623.68 | P32: =_xlfn.FORECAST.ETS(P$27,$E32:O32,$E$27:O$27) -> 62955.109 | ... T32: =_xlfn.FORECAST.ETS(T$27,$E32:S32,$E$27:S$27) -> 51987.35
B33: 11264 | C33: Support | D33: Call Center | E33: 27416 | F33: 26554 | G33: 24330 | H33: 22338 | I33: =_xlfn.FORECAST.ETS(I$27,$E33:H33,$E$27:H$27) -> 20784.677 | J33: =_xlfn.FORECAST.ETS(J$27,$E33:I33,$E$27:I$27) -> 18966.367 | K33: =_xlfn.FORECAST.ETS(K$27,$E33:J33,$E$27:J$27) -> 17138.765 | L33: =_xlfn.FORECAST.ETS(L$27,$E33:K33,$E$27:K$27) -> 15398.473 | M33: =_xlfn.FORECAST.ETS(M$27,$E33:L33,$E$27:L$27) -> 13625.108 | N33: =_xlfn.FORECAST.ETS(N$27,$E33:M33,$E$27:M$27) -> 11459.691 | O33: =_xlfn.FORECAST.ETS(O$27,$E33:N33,$E$27:N$27) -> 10235.714 | P33: =_xlfn.FORECAST.ETS(P$27,$E33:O33,$E$27:O$27) -> 8271.2763 | ... T33: =_xlfn.FORECAST.ETS(T$27,$E33:S33,$E$27:S$27) -> 825.90662
B34: 11267 | C34: HR | D34: Recruiting Events | E34: 41696 | F34: 41696 | G34: 42558 | H34: 45448 | I34: =_xlfn.FORECAST.ETS(I$27,$E34:H34,$E$27:H$27) -> 46256.947 | J34: =_xlfn.FORECAST.ETS(J$27,$E34:I34,$E$27:I$27) -> 47704.638 | K34: =_xlfn.FORECAST.ETS(K$27,$E34:J34,$E$27:J$27) -> 49150.171 | L34: =_xlfn.FORECAST.ETS(L$27,$E34:K34,$E$27:K$27) -> 50452.329 | M34: =_xlfn.FORECAST.ETS(M$27,$E34:L34,$E$27:L$27) -> 51824.343 | N34: =_xlfn.FORECAST.ETS(N$27,$E34:M34,$E$27:M$27) -> 53196.599 | O34: =_xlfn.FORECAST.ETS(O$27,$E34:N34,$E$27:N$27) -> 54569.117 | P34: =_xlfn.FORECAST.ETS(P$27,$E34:O34,$E$27:O$27) -> 55941.82 | ... T34: =_xlfn.FORECAST.ETS(T$27,$E34:S34,$E$27:S$27) -> 61433.162
B35: 11268 | C35: HR | D35: Meetups | E35: 60285 | F35: 61225 | G35: 68994 | H35: 72410 | I35: =_xlfn.FORECAST.ETS(I$27,$E35:H35,$E$27:H$27) -> 76705.607 | J35: =_xlfn.FORECAST.ETS(J$27,$E35:I35,$E$27:I$27) -> 80731.326 | K35: =_xlfn.FORECAST.ETS(K$27,$E35:J35,$E$27:J$27) -> 87089.658 | L35: =_xlfn.FORECAST.ETS(L$27,$E35:K35,$E$27:K$27) -> 90875.73 | M35: =_xlfn.FORECAST.ETS(M$27,$E35:L35,$E$27:L$27) -> 96948.062 | N35: =_xlfn.FORECAST.ETS(N$27,$E35:M35,$E$27:M$27) -> 100800.22 | O35: =_xlfn.FORECAST.ETS(O$27,$E35:N35,$E$27:N$27) -> 106865.98 | P35: =_xlfn.FORECAST.ETS(P$27,$E35:O35,$E$27:O$27) -> 111036.03 | ... T35: =_xlfn.FORECAST.ETS(T$27,$E35:S35,$E$27:S$27) -> 131085.88
B37: 3. Worst Case | E37: Actuals | I37: Forecast
B38: Account # | C38: Department | D38: Description | E38: 45559 | F38: 45589 | G38: 45620 | H38: 45650 | I38: 45681 | J38: 45712 | K38: 45740 | L38: 45771 | M38: 45801 | N38: 45832 | O38: 45862 | P38: 45893 | Q38: 45924 | R38: 45954 | S38: 45985 | T38: 46015
B39: 11256 | C39: Marketing | D39: Paid Ads | E39: 22992 | F39: 24001 | G39: 26558 | H39: 25446 | I39: =I28*(1+$C$2) -> 34917.689 | J39: =J28*(1+$C$2) -> 34999.372 | K39: =K28*(1+$C$2) -> 37128.286 | L39: =L28*(1+$C$2) -> 37051.862 | M39: =M28*(1+$C$2) -> 39131.751 | N39: =N28*(1+$C$2) -> 39145.235 | O39: =O28*(1+$C$2) -> 41173.846 | P39: =P28*(1+$C$2) -> 41188.471 | ... T39: =T28*(1+$C$2) -> 45261.932
B40: 11257 | C40: Marketing | D40: Infuencers | E40: 53326 | F40: 54223 | G40: 51000 | H40: 50000 | I40: =I29*(1+$C$2) -> 63516.107 | J40: =J29*(1+$C$2) -> 61861.756 | K40: =K29*(1+$C$2) -> 59597.227 | L40: =L29*(1+$C$2) -> 57968.808 | M40: =M29*(1+$C$2) -> 55733.151 | N40: =N29*(1+$C$2) -> 54157.343 | O40: =O29*(1+$C$2) -> 51611.558 | P40: =P29*(1+$C$2) -> 50085.461 | ... T40: =T29*(1+$C$2) -> 42015.045
B41: 11259 | C41: Engineering | D41: Consulting | E41: 35888 | F41: 36880 | G41: 37995 | H41: 40000 | I41: =I30*(1+$C$2) -> 53539.163 | J41: =J30*(1+$C$2) -> 55397.773 | K41: =K30*(1+$C$2) -> 57247.018 | L41: =L30*(1+$C$2) -> 59038.085 | M41: =M30*(1+$C$2) -> 60858.938 | N41: =N30*(1+$C$2) -> 62679.904 | O41: =O30*(1+$C$2) -> 64500.992 | P41: =P30*(1+$C$2) -> 66322.167 | ... T41: =T30*(1+$C$2) -> 73607.14
B42: 11260 | C42: Engineering | D42: Travel | E42: 87942 | F42: 85224 | G42: 82469 | H42: 81005 | I42: =I31*(1+$C$2) -> 101956.26 | J42: =J31*(1+$C$2) -> 99031.456 | K42: =K31*(1+$C$2) -> 96086.205 | L42: =L31*(1+$C$2) -> 93095.483 | M42: =M31*(1+$C$2) -> 90131.461 | N42: =N31*(1+$C$2) -> 87165.747 | O42: =O31*(1+$C$2) -> 84198.921 | P42: =P31*(1+$C$2) -> 81224.948 | ... T42: =T31*(1+$C$2) -> 69348.261
B43: 11263 | C43: Support | D43: Software | E43: 92622 | F43: 90005 | G43: 87556 | H43: 84522 | I43: =I32*(1+$C$2) -> 106491.94 | J43: =J32*(1+$C$2) -> 102968.33 | K43: =K32*(1+$C$2) -> 99428.485 | L43: =L32*(1+$C$2) -> 95930.234 | M43: =M32*(1+$C$2) -> 92412.057 | N43: =N32*(1+$C$2) -> 88748.089 | O43: =O32*(1+$C$2) -> 85310.784 | P43: =P32*(1+$C$2) -> 81841.642 | ... T43: =T32*(1+$C$2) -> 67583.555
B44: 11264 | C44: Support | D44: Call Center | E44: 27416 | F44: 26554 | G44: 24330 | H44: 22338 | I44: =I33*(1+$C$2) -> 27020.08 | J44: =J33*(1+$C$2) -> 24656.278 | K44: =K33*(1+$C$2) -> 22280.395 | L44: =L33*(1+$C$2) -> 20018.015 | M44: =M33*(1+$C$2) -> 17712.641 | N44: =N33*(1+$C$2) -> 14897.598 | O44: =O33*(1+$C$2) -> 13306.428 | P44: =P33*(1+$C$2) -> 10752.659 | ... T44: =T33*(1+$C$2) -> 1073.6786
...

Sheet Income Statement
B2: Operating Expenses Scenario | C2: 1
A4: x | B4: Income Statement Forecast | C4: 45658 | D4: 45689 | E4: 45717 | F4: 45748 | G4: 45778 | H4: 45809 | I4: 45839 | J4: 45870 | K4: 45901 | L4: 45931 | M4: 45962 | N4: 45992
B5: in USD
B6: Revenue | C6: =C31 -> 492926.16 | D6: =D31 -> 485050.73 | E6: =E31 -> 484371.61 | F6: =F31 -> 475834.28 | G6: =G31 -> 475054.24 | H6: =H31 -> 467230.6 | I6: =I31 -> 597538 | J6: =J31 -> 587804.12 | ... N6: =N31 -> 562063.73
B7: COGS | C7: =C35 -> 147877.85 | D7: =D35 -> 145515.22 | E7: =E35 -> 145311.48 | F7: =F35 -> 142750.28 | G7: =G35 -> 142516.27 | H7: =H35 -> 140169.18 | I7: =I35 -> 179261.4 | J7: =J35 -> 176341.23 | ... N7: =N35 -> 168619.12
B8: Gross Profit | C8: =C6-C7 -> 345048.31 | D8: =D6-D7 -> 339535.51 | E8: =E6-E7 -> 339060.12 | F8: =F6-F7 -> 333083.99 | G8: =G6-G7 -> 332537.97 | H8: =H6-H7 -> 327061.42 | I8: =I6-I7 -> 418276.6 | J8: =J6-J7 -> 411462.88 | ... N8: =N6-N7 -> 393444.61
B10: Operating expenses:
B11: {=_xlfn.UNIQUE('Actual Expenses'!C6:C13)} -> Marketing | C11: =SUMIFS(Forecast!I$6:I$13,Forecast!$C$6:$C$13,'Income Statement'!$B11) -> 53002.813 | D11: =SUMIFS(Forecast!J$6:J$13,Forecast!$C$6:$C$13,'Income Statement'!$B11) -> 52155.992 | E11: =SUMIFS(Forecast!K$6:K$13,Forecast!$C$6:$C$13,'Income Statement'!$B11) -> 52082.968 | F11: =SUMIFS(Forecast!L$6:L$13,Forecast!$C$6:$C$13,'Income Statement'!$B11) -> 51164.976 | G11: =SUMIFS(Forecast!M$6:M$13,Forecast!$C$6:$C$13,'Income Statement'!$B11) -> 51081.101 | H11: =SUMIFS(Forecast!N$6:N$13,Forecast!$C$6:$C$13,'Income Statement'!$B11) -> 50239.85 | I11: =SUMIFS(Forecast!O$6:O$13,Forecast!$C$6:$C$13,'Income Statement'!$B11) -> 49961.371 | J11: =SUMIFS(Forecast!P$6:P$13,Forecast!$C$6:$C$13,'Income Statement'!$B11) -> 49147.501 | ... N11: =SUMIFS(Forecast!T$6:T$13,Forecast!$C$6:$C$13,'Income Statement'!$B11) -> 46995.295
B12: Engineering | C12: =SUMIFS(Forecast!I$6:I$13,Forecast!$C$6:$C$13,'Income Statement'!$B12) -> 83728.304 | D12: =SUMIFS(Forecast!J$6:J$13,Forecast!$C$6:$C$13,'Income Statement'!$B12) -> 83154.201 | E12: =SUMIFS(Forecast!K$6:K$13,Forecast!$C$6:$C$13,'Income Statement'!$B12) -> 82564.043 | F12: =SUMIFS(Forecast!L$6:L$13,Forecast!$C$6:$C$13,'Income Statement'!$B12) -> 81918.076 | G12: =SUMIFS(Forecast!M$6:M$13,Forecast!$C$6:$C$13,'Income Statement'!$B12) -> 81302.522 | H12: =SUMIFS(Forecast!N$6:N$13,Forecast!$C$6:$C$13,'Income Statement'!$B12) -> 80686.12 | I12: =SUMIFS(Forecast!O$6:O$13,Forecast!$C$6:$C$13,'Income Statement'!$B12) -> 80069.184 | J12: =SUMIFS(Forecast!P$6:P$13,Forecast!$C$6:$C$13,'Income Statement'!$B12) -> 79448.446 | ... N12: =SUMIFS(Forecast!T$6:T$13,Forecast!$C$6:$C$13,'Income Statement'!$B12) -> 76975.985
B13: Support | C13: =SUMIFS(Forecast!I$6:I$13,Forecast!$C$6:$C$13,'Income Statement'!$B13) -> 71891.087 | D13: =SUMIFS(Forecast!J$6:J$13,Forecast!$C$6:$C$13,'Income Statement'!$B13) -> 68720.943 | E13: =SUMIFS(Forecast!K$6:K$13,Forecast!$C$6:$C$13,'Income Statement'!$B13) -> 65535.551 | F13: =SUMIFS(Forecast!L$6:L$13,Forecast!$C$6:$C$13,'Income Statement'!$B13) -> 62433.673 | G13: =SUMIFS(Forecast!M$6:M$13,Forecast!$C$6:$C$13,'Income Statement'!$B13) -> 59297.914 | H13: =SUMIFS(Forecast!N$6:N$13,Forecast!$C$6:$C$13,'Income Statement'!$B13) -> 55809.216 | I13: =SUMIFS(Forecast!O$6:O$13,Forecast!$C$6:$C$13,'Income Statement'!$B13) -> 53101.576 | J13: =SUMIFS(Forecast!P$6:P$13,Forecast!$C$6:$C$13,'Income Statement'!$B13) -> 49858.47 | ... N13: =SUMIFS(Forecast!T$6:T$13,Forecast!$C$6:$C$13,'Income Statement'!$B13) -> 36969.279
B14: HR | C14: =SUMIFS(Forecast!I$6:I$13,Forecast!$C$6:$C$13,'Income Statement'!$B14) -> 86073.787 | D14: =SUMIFS(Forecast!J$6:J$13,Forecast!$C$6:$C$13,'Income Statement'!$B14) -> 89905.175 | E14: =SUMIFS(Forecast!K$6:K$13,Forecast!$C$6:$C$13,'Income Statement'!$B14) -> 95367.88 | F14: =SUMIFS(Forecast!L$6:L$13,Forecast!$C$6:$C$13,'Income Statement'!$B14) -> 98929.641 | G14: =SUMIFS(Forecast!M$6:M$13,Forecast!$C$6:$C$13,'Income Statement'!$B14) -> 104140.68 | H14: =SUMIFS(Forecast!N$6:N$13,Forecast!$C$6:$C$13,'Income Statement'!$B14) -> 107797.77 | I14: =SUMIFS(Forecast!O$6:O$13,Forecast!$C$6:$C$13,'Income Statement'!$B14) -> 113004.57 | J14: =SUMIFS(Forecast!P$6:P$13,Forecast!$C$6:$C$13,'Income Statement'!$B14) -> 116884.5 | ... N14: =SUMIFS(Forecast!T$6:T$13,Forecast!$C$6:$C$13,'Income Statement'!$B14) -> 134763.33
B15: Total operating expenses | C15: =SUM(C11:C14) -> 294695.99 | D15: =SUM(D11:D14) -> 293936.31 | E15: =SUM(E11:E14) -> 295550.44 | F15: =SUM(F11:F14) -> 294446.37 | G15: =SUM(G11:G14) -> 295822.22 | H15: =SUM(H11:H14) -> 294532.96 | I15: =SUM(I11:I14) -> 296136.7 | J15: =SUM(J11:J14) -> 295338.92 | ... N15: =SUM(N11:N14) -> 295703.89
B16: Operating income | C16: =C8-C15 -> 50352.323 | D16: =D8-D15 -> 45599.198 | E16: =E8-E15 -> 43509.682 | F16: =F8-F15 -> 38637.628 | G16: =G8-G15 -> 36715.747 | H16: =H8-H15 -> 32528.464 | I16: =I8-I15 -> 122139.9 | J16: =J8-J15 -> 116123.97 | ... N16: =N8-N15 -> 97740.723
B18: Other income / (expense), net | C18: =C38 -> 3696.9462 | D18: =D38 -> 3637.8804 | E18: =E38 -> 3632.787 | F18: =F38 -> 3568.7571 | G18: =G38 -> 3562.9068 | H18: =H38 -> 3504.2295 | I18: =I38 -> 4481.535 | J18: =J38 -> 4408.5309 | ... N18: =N38 -> 4215.478
B19: Pre-tax income | C19: =C16-C18 -> 46655.377 | D19: =D16-D18 -> 41961.317 | E19: =E16-E18 -> 39876.895 | F19: =F16-F18 -> 35068.871 | G19: =G16-G18 -> 33152.84 | H19: =H16-H18 -> 29024.234 | I19: =I16-I18 -> 117658.37 | J19: =J16-J18 -> 111715.43 | ... N19: =N16-N18 -> 93525.245
B21: Taxes | C21: =C19*$C$40 -> 11663.844 | D21: =D19*$C$40 -> 10490.329 | E21: =E19*$C$40 -> 9969.2238 | F21: =F19*$C$40 -> 8767.2178 | G21: =G19*$C$40 -> 8288.21 | H21: =H19*$C$40 -> 7256.0586 | I21: =I19*$C$40 -> 29414.592 | J21: =J19*$C$40 -> 27928.859 | ... N21: =N19*$C$40 -> 23381.311
B22: Net Income | C22: =C19-C21 -> 34991.532 | D22: =D19-D21 -> 31470.988 | E22: =E19-E21 -> 29907.671 | F22: =F19-F21 -> 26301.653 | G22: =G19-G21 -> 24864.63 | H22: =H19-H21 -> 21768.176 | I22: =I19-I21 -> 88243.775 | J22: =J19-J21 -> 83786.576 | ... N22: =N19-N21 -> 70143.934
A25: x | B25: Assumptions
B26: Revenue
B27: Customer Acquisition Cost | C27: 30 | D27: 30 | E27: 30 | F27: 30 | G27: 30 | H27: 30 | I27: 25 | J27: 25 | K27: 25 | L27: 25 | M27: 25 | N27: 25
B28: Price | C28: 279 | D28: 279 | E28: 279 | F28: 279 | G28: 279 | H28: 279 | I28: 299 | J28: 299 | K28: 299 | L28: 299 | M28: 299 | N28: 299
B30: Units Sold | C30: =C11/C27 -> 1766.7604 | D30: =D11/D27 -> 1738.5331 | E30: =E11/E27 -> 1736.0989 | F30: =F11/F27 -> 1705.4992 | G30: =G11/G27 -> 1702.7034 | H30: =H11/H27 -> 1674.6617 | I30: =I11/I27 -> 1998.4549 | J30: =J11/J27 -> 1965.9001 | ... N30: =N11/N27 -> 1879.8118
B31: Revenue | C31: =C30*C28 -> 492926.16 | D31: =D30*D28 -> 485050.73 | E31: =E30*E28 -> 484371.61 | F31: =F30*F28 -> 475834.28 | G31: =G30*G28 -> 475054.24 | H31: =H30*H28 -> 467230.6 | I31: =I30*I28 -> 597538 | J31: =J30*J28 -> 587804.12 | ... N31: =N30*N28 -> 562063.73
B33: Other
B34: COGS % of Revenue | C34: 0.3 | D34: 0.3 | E34: 0.3 | F34: 0.3 | G34: 0.3 | H34: 0.3 | I34: 0.3 | J34: 0.3 | K34: 0.3 | L34: 0.3 | M34: 0.3 | N34: 0.3
B35: COGS | C35: =C31*C34 -> 147877.85 | D35: =D31*D34 -> 145515.22 | E35: =E31*E34 -> 145311.48 | F35: =F31*F34 -> 142750.28 | G35: =G31*G34 -> 142516.27 | H35: =H31*H34 -> 140169.18 | I35: =I31*I34 -> 179261.4 | J35: =J31*J34 -> 176341.23 | ... N35: =N31*N34 -> 168619.12
B37: Other income / (expense), net % of COGS | C37: 0.025 | D37: 0.025 | E37: 0.025 | F37: 0.025 | G37: 0.025 | H37: 0.025 | I37: 0.025 | J37: 0.025 | K37: 0.025 | L37: 0.025 | M37: 0.025 | N37: 0.025
B38: Other income / (expense), net | C38: =C35*C37 -> 3696.9462 | D38: =D35*D37 -> 3637.8804 | E38: =E35*E37 -> 3632.787 | F38: =F35*F37 -> 3568.7571 | G38: =G35*G37 -> 3562.9068 | H38: =H35*H37 -> 3504.2295 | I38: =I35*I37 -> 4481.535 | J38: =J35*J37 -> 4408.5309 | ... N38: =N35*N37 -> 4215.478
A40: x | B40: Tax Rate | C40: 0.25

Sheet Visuals
B2: in USD | C2: ='Income Statement'!C5 -> 0 | D2: =EDATE(C2,1) -> 31 | E2: =EDATE(D2,1) -> 59 | F2: =EDATE(E2,1) -> 88 | G2: =EDATE(F2,1) -> 119 | H2: =EDATE(G2,1) -> 149 | I2: =EDATE(H2,1) -> 180 | J2: =EDATE(I2,1) -> 210 | K2: =EDATE(J2,1) -> 241 | ... N2: =EDATE(M2,1) -> 333
B3: Revenue | C3: ='Income Statement'!C6 -> 492926.16 | D3: ='Income Statement'!D6 -> 485050.73 | E3: ='Income Statement'!E6 -> 484371.61 | F3: ='Income Statement'!F6 -> 475834.28 | G3: ='Income Statement'!G6 -> 475054.24 | H3: ='Income Statement'!H6 -> 467230.6 | I3: ='Income Statement'!I6 -> 597538 | J3: ='Income Statement'!J6 -> 587804.12 | ... N3: ='Income Statement'!N6 -> 562063.73
B4: Profit Margin | C4: ='Income Statement'!C22/Visuals!C3 -> 0.070987371 | D4: ='Income Statement'!D22/Visuals!D3 -> 0.064881849 | E4: ='Income Statement'!E22/Visuals!E3 -> 0.061745302 | F4: ='Income Statement'!F22/Visuals!F3 -> 0.055274819 | G4: ='Income Statement'!G22/Visuals!G3 -> 0.052340613 | H4: ='Income Statement'!H22/Visuals!H3 -> 0.04658979 | I4: ='Income Statement'!I22/Visuals!I3 -> 0.14767893 | J4: ='Income Statement'!J22/Visuals!J3 -> 0.14254166 | ... N4: ='Income Statement'!N22/Visuals!N3 -> 0.12479712
